INFO:root:Aplicativo iniciado
INFO:werkzeug: * Running on http://localhost:5000 (Press CTRL+C to quit)
INFO:werkzeug: * Restarting with stat
INFO:root:Aplicativo iniciado
WARNING:werkzeug: * Debugger is active!
INFO:werkzeug: * Debugger PIN: 113-951-105
INFO:werkzeug: * Detected change in 'c:\\Users\\Admin\\Desktop\\Leonardo Worm\\Testes\\Flask teste\\open_port_checker.py', reloading
INFO:werkzeug: * Restarting with stat
INFO:root:Aplicativo iniciado
WARNING:werkzeug: * Debugger is active!
INFO:werkzeug: * Debugger PIN: 113-951-105
INFO:werkzeug: * Detected change in 'c:\\Users\\Admin\\Desktop\\Leonardo Worm\\Testes\\Flask teste\\open_port_checker.py', reloading
INFO:werkzeug: * Restarting with stat
INFO:root:Aplicativo iniciado
INFO:werkzeug: * Running on http://localhost:5000 (Press CTRL+C to quit)
INFO:werkzeug: * Restarting with stat
INFO:root:Aplicativo iniciado
WARNING:werkzeug: * Debugger is active!
INFO:werkzeug: * Debugger PIN: 113-951-105
INFO:root:Aplicativo iniciado
INFO:werkzeug: * Running on http://localhost:5000 (Press CTRL+C to quit)
INFO:werkzeug: * Restarting with stat
INFO:root:Aplicativo iniciado
WARNING:werkzeug: * Debugger is active!
INFO:werkzeug: * Debugger PIN: 113-951-105
INFO:werkzeug:127.0.0.1 - - [16/Oct/2023 15:08:57] "[35m[1mGET / HTTP/1.1[0m" 500 -
INFO:werkzeug:127.0.0.1 - - [16/Oct/2023 15:08:57] "GET /?__debugger__=yes&cmd=resource&f=style.css HTTP/1.1" 200 -
INFO:werkzeug:127.0.0.1 - - [16/Oct/2023 15:08:57] "GET /?__debugger__=yes&cmd=resource&f=debugger.js HTTP/1.1" 200 -
INFO:werkzeug:127.0.0.1 - - [16/Oct/2023 15:08:57] "GET /?__debugger__=yes&cmd=resource&f=console.png HTTP/1.1" 200 -
INFO:werkzeug:127.0.0.1 - - [16/Oct/2023 15:08:57] "[36mGET /?__debugger__=yes&cmd=resource&f=console.png HTTP/1.1[0m" 304 -
INFO:root:Servidor Flask iniciado na porta 5001
INFO:root:Servidor Flask iniciado na porta 5000
INFO:root:Aplicativo iniciado
INFO:werkzeug: * Running on http://localhost:5000 (Press CTRL+C to quit)
INFO:werkzeug: * Restarting with stat
INFO:root:Aplicativo iniciado
WARNING:werkzeug: * Debugger is active!
INFO:werkzeug: * Debugger PIN: 113-951-105
INFO:werkzeug:127.0.0.1 - - [16/Oct/2023 15:10:17] "GET / HTTP/1.1" 200 -
INFO:werkzeug:127.0.0.1 - - [16/Oct/2023 15:10:17] "GET /static/style.css HTTP/1.1" 200 -
INFO:werkzeug:127.0.0.1 - - [16/Oct/2023 15:10:17] "GET /static/reset.css HTTP/1.1" 200 -
INFO:werkzeug:127.0.0.1 - - [16/Oct/2023 15:10:17] "[33mGET /favicon.ico HTTP/1.1[0m" 404 -
INFO:werkzeug:127.0.0.1 - - [16/Oct/2023 15:10:19] "GET /login HTTP/1.1" 200 -
INFO:werkzeug:127.0.0.1 - - [16/Oct/2023 15:10:19] "[36mGET /static/reset.css HTTP/1.1[0m" 304 -
INFO:werkzeug:127.0.0.1 - - [16/Oct/2023 15:10:19] "[36mGET /static/style.css HTTP/1.1[0m" 304 -
INFO:werkzeug: * Detected change in 'C:\\Users\\Admin\\Desktop\\Leonardo Worm\\Testes\\Flask teste\\app.py', reloading
INFO:werkzeug: * Restarting with stat
INFO:root:Aplicativo iniciado
WARNING:werkzeug: * Debugger is active!
INFO:werkzeug: * Debugger PIN: 113-951-105
INFO:werkzeug:127.0.0.1 - - [16/Oct/2023 15:11:03] "GET /login HTTP/1.1" 200 -
INFO:werkzeug:127.0.0.1 - - [16/Oct/2023 15:11:03] "GET /static/reset.css HTTP/1.1" 200 -
INFO:werkzeug:127.0.0.1 - - [16/Oct/2023 15:11:03] "GET /static/style.css HTTP/1.1" 200 -
INFO:werkzeug:127.0.0.1 - - [16/Oct/2023 15:11:03] "[33mGET /favicon.ico HTTP/1.1[0m" 404 -
INFO:werkzeug:127.0.0.1 - - [16/Oct/2023 15:11:12] "POST /login HTTP/1.1" 200 -
INFO:werkzeug:127.0.0.1 - - [16/Oct/2023 15:11:12] "[36mGET /static/reset.css HTTP/1.1[0m" 304 -
INFO:werkzeug:127.0.0.1 - - [16/Oct/2023 15:11:12] "[36mGET /static/style.css HTTP/1.1[0m" 304 -
INFO:werkzeug:127.0.0.1 - - [16/Oct/2023 15:11:15] "GET /register HTTP/1.1" 200 -
INFO:werkzeug:127.0.0.1 - - [16/Oct/2023 15:11:15] "[36mGET /static/reset.css HTTP/1.1[0m" 304 -
INFO:werkzeug:127.0.0.1 - - [16/Oct/2023 15:11:15] "[36mGET /static/style.css HTTP/1.1[0m" 304 -
INFO:werkzeug:127.0.0.1 - - [16/Oct/2023 15:11:27] "[36mGET /static/reset.css HTTP/1.1[0m" 304 -
INFO:werkzeug:127.0.0.1 - - [16/Oct/2023 15:11:27] "[36mGET /static/style.css HTTP/1.1[0m" 304 -
INFO:werkzeug:127.0.0.1 - - [16/Oct/2023 15:11:29] "[31m[1mGET /shutdown HTTP/1.1[0m" 405 -
INFO:werkzeug: * Detected change in 'C:\\Users\\Admin\\Desktop\\Leonardo Worm\\Testes\\Flask teste\\app.py', reloading
INFO:werkzeug: * Restarting with stat
INFO:root:Aplicativo iniciado
INFO:root:Servidor Gevent iniciado na porta 5001
INFO:root:Servidor Flask iniciado na porta 5000
INFO:root:Aplicativo iniciado
INFO:root:Servidor Gevent iniciado na porta 5000
INFO:root:Aplicativo iniciado
INFO:root:Servidor Gevent iniciado na porta 5000
INFO:root:Aplicativo iniciado
INFO:root:Servidor Gevent iniciado na porta 5000
INFO:root:Aplicativo iniciado
INFO:root:Servidor Gevent iniciado na porta 5000
INFO:root:Aplicativo iniciado
INFO:root:Servidor Gevent iniciado na porta 5000
INFO:root:Aplicativo iniciado
INFO:root:Servidor Gevent iniciado na porta 5000
INFO:root:Aplicativo iniciado
INFO:root:Servidor Gevent iniciado na porta 5000
INFO:root:Aplicativo iniciado
INFO:root:Servidor Gevent iniciado na porta 5000
INFO:root:Aplicativo iniciado
INFO:root:Servidor Gevent iniciado na porta 5000
INFO:root:Aplicativo iniciado
INFO:root:Servidor Gevent iniciado na porta 5000
INFO:root:Aplicativo iniciado
INFO:root:Servidor Gevent iniciado na porta 5000
INFO:root:Aplicativo iniciado
INFO:root:Servidor Gevent iniciado na porta 5000
INFO:root:Aplicativo iniciado
INFO:root:Servidor Gevent iniciado na porta 5000
INFO:root:Aplicativo iniciado
INFO:root:Servidor Gevent iniciado na porta 5000
INFO:root:Aplicativo iniciado
INFO:root:Servidor Gevent iniciado na porta 5000
INFO:root:Aplicativo iniciado
INFO:root:Servidor Gevent iniciado na porta 5000
INFO:root:Aplicativo iniciado
INFO:root:Servidor Gevent iniciado na porta 5000
ERROR:app:Exception on /register [POST]
Traceback (most recent call last):
  File "C:\Users\praus\Desktop\Trabalhos\Eu\Programacao\flaskteste\venv\lib\site-packages\flask\app.py", line 2077, in wsgi_app
    response = self.full_dispatch_request()
  File "C:\Users\praus\Desktop\Trabalhos\Eu\Programacao\flaskteste\venv\lib\site-packages\flask\app.py", line 1525, in full_dispatch_request
    rv = self.handle_user_exception(e)
  File "C:\Users\praus\Desktop\Trabalhos\Eu\Programacao\flaskteste\venv\lib\site-packages\flask\app.py", line 1523, in full_dispatch_request
    rv = self.dispatch_request()
  File "C:\Users\praus\Desktop\Trabalhos\Eu\Programacao\flaskteste\venv\lib\site-packages\flask\app.py", line 1509, in dispatch_request
    return self.ensure_sync(self.view_functions[rule.endpoint])(**req.view_args)
  File "C:\Users\praus\Desktop\Trabalhos\Eu\Programacao\flaskteste\app.py", line 114, in register
    new_user = User(username.lower().strip(), password.lower().strip())
TypeError: __init__() takes 1 positional argument but 3 were given
ERROR:app:Exception on /register [POST]
Traceback (most recent call last):
  File "C:\Users\praus\Desktop\Trabalhos\Eu\Programacao\flaskteste\venv\lib\site-packages\flask\app.py", line 2077, in wsgi_app
    response = self.full_dispatch_request()
  File "C:\Users\praus\Desktop\Trabalhos\Eu\Programacao\flaskteste\venv\lib\site-packages\flask\app.py", line 1525, in full_dispatch_request
    rv = self.handle_user_exception(e)
  File "C:\Users\praus\Desktop\Trabalhos\Eu\Programacao\flaskteste\venv\lib\site-packages\flask\app.py", line 1523, in full_dispatch_request
    rv = self.dispatch_request()
  File "C:\Users\praus\Desktop\Trabalhos\Eu\Programacao\flaskteste\venv\lib\site-packages\flask\app.py", line 1509, in dispatch_request
    return self.ensure_sync(self.view_functions[rule.endpoint])(**req.view_args)
  File "C:\Users\praus\Desktop\Trabalhos\Eu\Programacao\flaskteste\app.py", line 114, in register
    new_user = User(username.lower().strip(), password.lower().strip())
TypeError: __init__() takes 1 positional argument but 3 were given
INFO:root:Aplicativo iniciado
INFO:root:Servidor Gevent iniciado na porta 5000
ERROR:app:Exception on /login [POST]
Traceback (most recent call last):
  File "C:\Users\praus\Desktop\Trabalhos\Eu\Programacao\flaskteste\venv\lib\site-packages\flask\app.py", line 2077, in wsgi_app
    response = self.full_dispatch_request()
  File "C:\Users\praus\Desktop\Trabalhos\Eu\Programacao\flaskteste\venv\lib\site-packages\flask\app.py", line 1525, in full_dispatch_request
    rv = self.handle_user_exception(e)
  File "C:\Users\praus\Desktop\Trabalhos\Eu\Programacao\flaskteste\venv\lib\site-packages\flask\app.py", line 1523, in full_dispatch_request
    rv = self.dispatch_request()
  File "C:\Users\praus\Desktop\Trabalhos\Eu\Programacao\flaskteste\venv\lib\site-packages\flask\app.py", line 1509, in dispatch_request
    return self.ensure_sync(self.view_functions[rule.endpoint])(**req.view_args)
  File "C:\Users\praus\Desktop\Trabalhos\Eu\Programacao\flaskteste\app.py", line 98, in login
    user = User.query.filter_by(username).first()
TypeError: Query.filter_by() takes 1 positional argument but 2 were given
INFO:root:Aplicativo iniciado
INFO:root:Servidor Gevent iniciado na porta 5000
ERROR:app:Exception on /register [POST]
Traceback (most recent call last):
  File "C:\Users\praus\Desktop\Trabalhos\Eu\Programacao\flaskteste\venv\lib\site-packages\flask\app.py", line 2077, in wsgi_app
    response = self.full_dispatch_request()
  File "C:\Users\praus\Desktop\Trabalhos\Eu\Programacao\flaskteste\venv\lib\site-packages\flask\app.py", line 1525, in full_dispatch_request
    rv = self.handle_user_exception(e)
  File "C:\Users\praus\Desktop\Trabalhos\Eu\Programacao\flaskteste\venv\lib\site-packages\flask\app.py", line 1523, in full_dispatch_request
    rv = self.dispatch_request()
  File "C:\Users\praus\Desktop\Trabalhos\Eu\Programacao\flaskteste\venv\lib\site-packages\flask\app.py", line 1509, in dispatch_request
    return self.ensure_sync(self.view_functions[rule.endpoint])(**req.view_args)
  File "C:\Users\praus\Desktop\Trabalhos\Eu\Programacao\flaskteste\app.py", line 116, in register
    new_user = User(username, password)
TypeError: __init__() takes 1 positional argument but 3 were given
INFO:root:Aplicativo iniciado
INFO:root:Servidor Gevent iniciado na porta 5000
ERROR:app:Exception on /register [POST]
Traceback (most recent call last):
  File "C:\Users\praus\Desktop\Trabalhos\Eu\Programacao\flaskteste\venv\lib\site-packages\flask\app.py", line 2077, in wsgi_app
    response = self.full_dispatch_request()
  File "C:\Users\praus\Desktop\Trabalhos\Eu\Programacao\flaskteste\venv\lib\site-packages\flask\app.py", line 1525, in full_dispatch_request
    rv = self.handle_user_exception(e)
  File "C:\Users\praus\Desktop\Trabalhos\Eu\Programacao\flaskteste\venv\lib\site-packages\flask\app.py", line 1523, in full_dispatch_request
    rv = self.dispatch_request()
  File "C:\Users\praus\Desktop\Trabalhos\Eu\Programacao\flaskteste\venv\lib\site-packages\flask\app.py", line 1509, in dispatch_request
    return self.ensure_sync(self.view_functions[rule.endpoint])(**req.view_args)
  File "C:\Users\praus\Desktop\Trabalhos\Eu\Programacao\flaskteste\app.py", line 118, in register
    new_user = User(username, password)
TypeError: __init__() takes 1 positional argument but 3 were given
ERROR:app:Exception on /register [POST]
Traceback (most recent call last):
  File "C:\Users\praus\Desktop\Trabalhos\Eu\Programacao\flaskteste\venv\lib\site-packages\flask\app.py", line 2077, in wsgi_app
    response = self.full_dispatch_request()
  File "C:\Users\praus\Desktop\Trabalhos\Eu\Programacao\flaskteste\venv\lib\site-packages\flask\app.py", line 1525, in full_dispatch_request
    rv = self.handle_user_exception(e)
  File "C:\Users\praus\Desktop\Trabalhos\Eu\Programacao\flaskteste\venv\lib\site-packages\flask\app.py", line 1523, in full_dispatch_request
    rv = self.dispatch_request()
  File "C:\Users\praus\Desktop\Trabalhos\Eu\Programacao\flaskteste\venv\lib\site-packages\flask\app.py", line 1509, in dispatch_request
    return self.ensure_sync(self.view_functions[rule.endpoint])(**req.view_args)
  File "C:\Users\praus\Desktop\Trabalhos\Eu\Programacao\flaskteste\app.py", line 118, in register
    new_user = User(username, password)
TypeError: __init__() takes 1 positional argument but 3 were given
INFO:root:Aplicativo iniciado
INFO:root:Servidor Gevent iniciado na porta 5000
ERROR:app:Exception on /login [POST]
Traceback (most recent call last):
  File "C:\Users\praus\Desktop\Trabalhos\Eu\Programacao\flaskteste\venv\lib\site-packages\flask\app.py", line 2077, in wsgi_app
    response = self.full_dispatch_request()
  File "C:\Users\praus\Desktop\Trabalhos\Eu\Programacao\flaskteste\venv\lib\site-packages\flask\app.py", line 1525, in full_dispatch_request
    rv = self.handle_user_exception(e)
  File "C:\Users\praus\Desktop\Trabalhos\Eu\Programacao\flaskteste\venv\lib\site-packages\flask\app.py", line 1523, in full_dispatch_request
    rv = self.dispatch_request()
  File "C:\Users\praus\Desktop\Trabalhos\Eu\Programacao\flaskteste\venv\lib\site-packages\flask\app.py", line 1509, in dispatch_request
    return self.ensure_sync(self.view_functions[rule.endpoint])(**req.view_args)
  File "C:\Users\praus\Desktop\Trabalhos\Eu\Programacao\flaskteste\app.py", line 99, in login
    user = User.query.filter_by(username).first()
TypeError: Query.filter_by() takes 1 positional argument but 2 were given
INFO:root:Aplicativo iniciado
INFO:root:Servidor Gevent iniciado na porta 5000
INFO:root:Aplicativo iniciado
INFO:root:Servidor Gevent iniciado na porta 5000
INFO:root:Aplicativo iniciado
INFO:root:Servidor Gevent iniciado na porta 5000
INFO:root:Aplicativo iniciado
INFO:root:Servidor Gevent iniciado na porta 5000
ERROR:app:Exception on /login [POST]
Traceback (most recent call last):
  File "C:\Users\praus\Desktop\Trabalhos\Eu\Programacao\flaskteste\venv\lib\site-packages\flask\app.py", line 2077, in wsgi_app
    response = self.full_dispatch_request()
  File "C:\Users\praus\Desktop\Trabalhos\Eu\Programacao\flaskteste\venv\lib\site-packages\flask\app.py", line 1525, in full_dispatch_request
    rv = self.handle_user_exception(e)
  File "C:\Users\praus\Desktop\Trabalhos\Eu\Programacao\flaskteste\venv\lib\site-packages\flask\app.py", line 1523, in full_dispatch_request
    rv = self.dispatch_request()
  File "C:\Users\praus\Desktop\Trabalhos\Eu\Programacao\flaskteste\venv\lib\site-packages\flask\app.py", line 1509, in dispatch_request
    return self.ensure_sync(self.view_functions[rule.endpoint])(**req.view_args)
  File "C:\Users\praus\Desktop\Trabalhos\Eu\Programacao\flaskteste\app.py", line 104, in login
    raise ValidationError("Username and password do not match!")
wtforms.validators.ValidationError: Username and password do not match!
INFO:root:Aplicativo iniciado
INFO:root:Servidor Gevent iniciado na porta 5000
INFO:root:Aplicativo iniciado
INFO:root:Servidor Gevent iniciado na porta 5000
INFO:root:Aplicativo iniciado
INFO:root:Servidor Gevent iniciado na porta 5000
INFO:root:Aplicativo iniciado
INFO:root:Servidor Gevent iniciado na porta 5000
INFO:root:Aplicativo iniciado
INFO:root:Servidor Gevent iniciado na porta 5000
INFO:root:Aplicativo iniciado
INFO:root:Servidor Gevent iniciado na porta 5000
ERROR:app:Exception on /dashboard [GET]
Traceback (most recent call last):
  File "C:\Users\praus\Desktop\Trabalhos\Eu\Programacao\flaskteste\venv\lib\site-packages\sqlalchemy\engine\base.py", line 1819, in _execute_context
    self.dialect.do_execute(
  File "C:\Users\praus\Desktop\Trabalhos\Eu\Programacao\flaskteste\venv\lib\site-packages\sqlalchemy\engine\default.py", line 732, in do_execute
    cursor.execute(statement, parameters)
sqlite3.OperationalError: no such table: client_items

The above exception was the direct cause of the following exception:

Traceback (most recent call last):
  File "C:\Users\praus\Desktop\Trabalhos\Eu\Programacao\flaskteste\venv\lib\site-packages\flask\app.py", line 2077, in wsgi_app
    response = self.full_dispatch_request()
  File "C:\Users\praus\Desktop\Trabalhos\Eu\Programacao\flaskteste\venv\lib\site-packages\flask\app.py", line 1525, in full_dispatch_request
    rv = self.handle_user_exception(e)
  File "C:\Users\praus\Desktop\Trabalhos\Eu\Programacao\flaskteste\venv\lib\site-packages\flask\app.py", line 1523, in full_dispatch_request
    rv = self.dispatch_request()
  File "C:\Users\praus\Desktop\Trabalhos\Eu\Programacao\flaskteste\venv\lib\site-packages\flask\app.py", line 1509, in dispatch_request
    return self.ensure_sync(self.view_functions[rule.endpoint])(**req.view_args)
  File "C:\Users\praus\Desktop\Trabalhos\Eu\Programacao\flaskteste\venv\lib\site-packages\flask_login\utils.py", line 277, in decorated_view
    return current_app.ensure_sync(func)(*args, **kwargs)
  File "C:\Users\praus\Desktop\Trabalhos\Eu\Programacao\flaskteste\app.py", line 157, in dashboard
    client_items = ClientItem.query.all()
  File "C:\Users\praus\Desktop\Trabalhos\Eu\Programacao\flaskteste\venv\lib\site-packages\sqlalchemy\orm\query.py", line 2768, in all
    return self._iter().all()
  File "C:\Users\praus\Desktop\Trabalhos\Eu\Programacao\flaskteste\venv\lib\site-packages\sqlalchemy\orm\query.py", line 2903, in _iter
    result = self.session.execute(
  File "C:\Users\praus\Desktop\Trabalhos\Eu\Programacao\flaskteste\venv\lib\site-packages\sqlalchemy\orm\session.py", line 1692, in execute
    result = conn._execute_20(statement, params or {}, execution_options)
  File "C:\Users\praus\Desktop\Trabalhos\Eu\Programacao\flaskteste\venv\lib\site-packages\sqlalchemy\engine\base.py", line 1631, in _execute_20
    return meth(self, args_10style, kwargs_10style, execution_options)
  File "C:\Users\praus\Desktop\Trabalhos\Eu\Programacao\flaskteste\venv\lib\site-packages\sqlalchemy\sql\elements.py", line 325, in _execute_on_connection
    return connection._execute_clauseelement(
  File "C:\Users\praus\Desktop\Trabalhos\Eu\Programacao\flaskteste\venv\lib\site-packages\sqlalchemy\engine\base.py", line 1498, in _execute_clauseelement
    ret = self._execute_context(
  File "C:\Users\praus\Desktop\Trabalhos\Eu\Programacao\flaskteste\venv\lib\site-packages\sqlalchemy\engine\base.py", line 1862, in _execute_context
    self._handle_dbapi_exception(
  File "C:\Users\praus\Desktop\Trabalhos\Eu\Programacao\flaskteste\venv\lib\site-packages\sqlalchemy\engine\base.py", line 2043, in _handle_dbapi_exception
    util.raise_(
  File "C:\Users\praus\Desktop\Trabalhos\Eu\Programacao\flaskteste\venv\lib\site-packages\sqlalchemy\util\compat.py", line 207, in raise_
    raise exception
  File "C:\Users\praus\Desktop\Trabalhos\Eu\Programacao\flaskteste\venv\lib\site-packages\sqlalchemy\engine\base.py", line 1819, in _execute_context
    self.dialect.do_execute(
  File "C:\Users\praus\Desktop\Trabalhos\Eu\Programacao\flaskteste\venv\lib\site-packages\sqlalchemy\engine\default.py", line 732, in do_execute
    cursor.execute(statement, parameters)
sqlalchemy.exc.OperationalError: (sqlite3.OperationalError) no such table: client_items
[SQL: SELECT client_items.id AS client_items_id, client_items.cpf AS client_items_cpf, client_items.name AS client_items_name, client_items.birthday AS client_items_birthday, client_items.client_id AS client_items_client_id 
FROM client_items]
(Background on this error at: https://sqlalche.me/e/14/e3q8)
ERROR:app:Exception on /dashboard [GET]
Traceback (most recent call last):
  File "C:\Users\praus\Desktop\Trabalhos\Eu\Programacao\flaskteste\venv\lib\site-packages\sqlalchemy\engine\base.py", line 1819, in _execute_context
    self.dialect.do_execute(
  File "C:\Users\praus\Desktop\Trabalhos\Eu\Programacao\flaskteste\venv\lib\site-packages\sqlalchemy\engine\default.py", line 732, in do_execute
    cursor.execute(statement, parameters)
sqlite3.OperationalError: no such table: client_items

The above exception was the direct cause of the following exception:

Traceback (most recent call last):
  File "C:\Users\praus\Desktop\Trabalhos\Eu\Programacao\flaskteste\venv\lib\site-packages\flask\app.py", line 2077, in wsgi_app
    response = self.full_dispatch_request()
  File "C:\Users\praus\Desktop\Trabalhos\Eu\Programacao\flaskteste\venv\lib\site-packages\flask\app.py", line 1525, in full_dispatch_request
    rv = self.handle_user_exception(e)
  File "C:\Users\praus\Desktop\Trabalhos\Eu\Programacao\flaskteste\venv\lib\site-packages\flask\app.py", line 1523, in full_dispatch_request
    rv = self.dispatch_request()
  File "C:\Users\praus\Desktop\Trabalhos\Eu\Programacao\flaskteste\venv\lib\site-packages\flask\app.py", line 1509, in dispatch_request
    return self.ensure_sync(self.view_functions[rule.endpoint])(**req.view_args)
  File "C:\Users\praus\Desktop\Trabalhos\Eu\Programacao\flaskteste\venv\lib\site-packages\flask_login\utils.py", line 277, in decorated_view
    return current_app.ensure_sync(func)(*args, **kwargs)
  File "C:\Users\praus\Desktop\Trabalhos\Eu\Programacao\flaskteste\app.py", line 157, in dashboard
    client_items = ClientItem.query.all()
  File "C:\Users\praus\Desktop\Trabalhos\Eu\Programacao\flaskteste\venv\lib\site-packages\sqlalchemy\orm\query.py", line 2768, in all
    return self._iter().all()
  File "C:\Users\praus\Desktop\Trabalhos\Eu\Programacao\flaskteste\venv\lib\site-packages\sqlalchemy\orm\query.py", line 2903, in _iter
    result = self.session.execute(
  File "C:\Users\praus\Desktop\Trabalhos\Eu\Programacao\flaskteste\venv\lib\site-packages\sqlalchemy\orm\session.py", line 1692, in execute
    result = conn._execute_20(statement, params or {}, execution_options)
  File "C:\Users\praus\Desktop\Trabalhos\Eu\Programacao\flaskteste\venv\lib\site-packages\sqlalchemy\engine\base.py", line 1631, in _execute_20
    return meth(self, args_10style, kwargs_10style, execution_options)
  File "C:\Users\praus\Desktop\Trabalhos\Eu\Programacao\flaskteste\venv\lib\site-packages\sqlalchemy\sql\elements.py", line 325, in _execute_on_connection
    return connection._execute_clauseelement(
  File "C:\Users\praus\Desktop\Trabalhos\Eu\Programacao\flaskteste\venv\lib\site-packages\sqlalchemy\engine\base.py", line 1498, in _execute_clauseelement
    ret = self._execute_context(
  File "C:\Users\praus\Desktop\Trabalhos\Eu\Programacao\flaskteste\venv\lib\site-packages\sqlalchemy\engine\base.py", line 1862, in _execute_context
    self._handle_dbapi_exception(
  File "C:\Users\praus\Desktop\Trabalhos\Eu\Programacao\flaskteste\venv\lib\site-packages\sqlalchemy\engine\base.py", line 2043, in _handle_dbapi_exception
    util.raise_(
  File "C:\Users\praus\Desktop\Trabalhos\Eu\Programacao\flaskteste\venv\lib\site-packages\sqlalchemy\util\compat.py", line 207, in raise_
    raise exception
  File "C:\Users\praus\Desktop\Trabalhos\Eu\Programacao\flaskteste\venv\lib\site-packages\sqlalchemy\engine\base.py", line 1819, in _execute_context
    self.dialect.do_execute(
  File "C:\Users\praus\Desktop\Trabalhos\Eu\Programacao\flaskteste\venv\lib\site-packages\sqlalchemy\engine\default.py", line 732, in do_execute
    cursor.execute(statement, parameters)
sqlalchemy.exc.OperationalError: (sqlite3.OperationalError) no such table: client_items
[SQL: SELECT client_items.id AS client_items_id, client_items.cpf AS client_items_cpf, client_items.name AS client_items_name, client_items.birthday AS client_items_birthday, client_items.client_id AS client_items_client_id 
FROM client_items]
(Background on this error at: https://sqlalche.me/e/14/e3q8)
INFO:root:Aplicativo iniciado
INFO:root:Servidor Gevent iniciado na porta 5000
ERROR:app:Exception on /dashboard [GET]
Traceback (most recent call last):
  File "C:\Users\praus\Desktop\Trabalhos\Eu\Programacao\flaskteste\venv\lib\site-packages\sqlalchemy\engine\base.py", line 1819, in _execute_context
    self.dialect.do_execute(
  File "C:\Users\praus\Desktop\Trabalhos\Eu\Programacao\flaskteste\venv\lib\site-packages\sqlalchemy\engine\default.py", line 732, in do_execute
    cursor.execute(statement, parameters)
sqlite3.OperationalError: no such table: client_items

The above exception was the direct cause of the following exception:

Traceback (most recent call last):
  File "C:\Users\praus\Desktop\Trabalhos\Eu\Programacao\flaskteste\venv\lib\site-packages\flask\app.py", line 2077, in wsgi_app
    response = self.full_dispatch_request()
  File "C:\Users\praus\Desktop\Trabalhos\Eu\Programacao\flaskteste\venv\lib\site-packages\flask\app.py", line 1525, in full_dispatch_request
    rv = self.handle_user_exception(e)
  File "C:\Users\praus\Desktop\Trabalhos\Eu\Programacao\flaskteste\venv\lib\site-packages\flask\app.py", line 1523, in full_dispatch_request
    rv = self.dispatch_request()
  File "C:\Users\praus\Desktop\Trabalhos\Eu\Programacao\flaskteste\venv\lib\site-packages\flask\app.py", line 1509, in dispatch_request
    return self.ensure_sync(self.view_functions[rule.endpoint])(**req.view_args)
  File "C:\Users\praus\Desktop\Trabalhos\Eu\Programacao\flaskteste\venv\lib\site-packages\flask_login\utils.py", line 277, in decorated_view
    return current_app.ensure_sync(func)(*args, **kwargs)
  File "C:\Users\praus\Desktop\Trabalhos\Eu\Programacao\flaskteste\app.py", line 157, in dashboard
    client_items = ClientItem.query.all()
  File "C:\Users\praus\Desktop\Trabalhos\Eu\Programacao\flaskteste\venv\lib\site-packages\sqlalchemy\orm\query.py", line 2768, in all
    return self._iter().all()
  File "C:\Users\praus\Desktop\Trabalhos\Eu\Programacao\flaskteste\venv\lib\site-packages\sqlalchemy\orm\query.py", line 2903, in _iter
    result = self.session.execute(
  File "C:\Users\praus\Desktop\Trabalhos\Eu\Programacao\flaskteste\venv\lib\site-packages\sqlalchemy\orm\session.py", line 1692, in execute
    result = conn._execute_20(statement, params or {}, execution_options)
  File "C:\Users\praus\Desktop\Trabalhos\Eu\Programacao\flaskteste\venv\lib\site-packages\sqlalchemy\engine\base.py", line 1631, in _execute_20
    return meth(self, args_10style, kwargs_10style, execution_options)
  File "C:\Users\praus\Desktop\Trabalhos\Eu\Programacao\flaskteste\venv\lib\site-packages\sqlalchemy\sql\elements.py", line 325, in _execute_on_connection
    return connection._execute_clauseelement(
  File "C:\Users\praus\Desktop\Trabalhos\Eu\Programacao\flaskteste\venv\lib\site-packages\sqlalchemy\engine\base.py", line 1498, in _execute_clauseelement
    ret = self._execute_context(
  File "C:\Users\praus\Desktop\Trabalhos\Eu\Programacao\flaskteste\venv\lib\site-packages\sqlalchemy\engine\base.py", line 1862, in _execute_context
    self._handle_dbapi_exception(
  File "C:\Users\praus\Desktop\Trabalhos\Eu\Programacao\flaskteste\venv\lib\site-packages\sqlalchemy\engine\base.py", line 2043, in _handle_dbapi_exception
    util.raise_(
  File "C:\Users\praus\Desktop\Trabalhos\Eu\Programacao\flaskteste\venv\lib\site-packages\sqlalchemy\util\compat.py", line 207, in raise_
    raise exception
  File "C:\Users\praus\Desktop\Trabalhos\Eu\Programacao\flaskteste\venv\lib\site-packages\sqlalchemy\engine\base.py", line 1819, in _execute_context
    self.dialect.do_execute(
  File "C:\Users\praus\Desktop\Trabalhos\Eu\Programacao\flaskteste\venv\lib\site-packages\sqlalchemy\engine\default.py", line 732, in do_execute
    cursor.execute(statement, parameters)
sqlalchemy.exc.OperationalError: (sqlite3.OperationalError) no such table: client_items
[SQL: SELECT client_items.id AS client_items_id, client_items.cpf AS client_items_cpf, client_items.name AS client_items_name, client_items.birthday AS client_items_birthday, client_items.client_id AS client_items_client_id 
FROM client_items]
(Background on this error at: https://sqlalche.me/e/14/e3q8)
INFO:root:Aplicativo iniciado
INFO:root:Servidor Gevent iniciado na porta 5000
ERROR:app:Exception on /dashboard [GET]
Traceback (most recent call last):
  File "C:\Users\praus\Desktop\Trabalhos\Eu\Programacao\flaskteste\venv\lib\site-packages\sqlalchemy\engine\base.py", line 1819, in _execute_context
    self.dialect.do_execute(
  File "C:\Users\praus\Desktop\Trabalhos\Eu\Programacao\flaskteste\venv\lib\site-packages\sqlalchemy\engine\default.py", line 732, in do_execute
    cursor.execute(statement, parameters)
sqlite3.OperationalError: no such column: client_items.client_id

The above exception was the direct cause of the following exception:

Traceback (most recent call last):
  File "C:\Users\praus\Desktop\Trabalhos\Eu\Programacao\flaskteste\venv\lib\site-packages\flask\app.py", line 2077, in wsgi_app
    response = self.full_dispatch_request()
  File "C:\Users\praus\Desktop\Trabalhos\Eu\Programacao\flaskteste\venv\lib\site-packages\flask\app.py", line 1525, in full_dispatch_request
    rv = self.handle_user_exception(e)
  File "C:\Users\praus\Desktop\Trabalhos\Eu\Programacao\flaskteste\venv\lib\site-packages\flask\app.py", line 1523, in full_dispatch_request
    rv = self.dispatch_request()
  File "C:\Users\praus\Desktop\Trabalhos\Eu\Programacao\flaskteste\venv\lib\site-packages\flask\app.py", line 1509, in dispatch_request
    return self.ensure_sync(self.view_functions[rule.endpoint])(**req.view_args)
  File "C:\Users\praus\Desktop\Trabalhos\Eu\Programacao\flaskteste\venv\lib\site-packages\flask_login\utils.py", line 277, in decorated_view
    return current_app.ensure_sync(func)(*args, **kwargs)
  File "C:\Users\praus\Desktop\Trabalhos\Eu\Programacao\flaskteste\app.py", line 157, in dashboard
    client_items = ClientItem.query.all()
  File "C:\Users\praus\Desktop\Trabalhos\Eu\Programacao\flaskteste\venv\lib\site-packages\sqlalchemy\orm\query.py", line 2768, in all
    return self._iter().all()
  File "C:\Users\praus\Desktop\Trabalhos\Eu\Programacao\flaskteste\venv\lib\site-packages\sqlalchemy\orm\query.py", line 2903, in _iter
    result = self.session.execute(
  File "C:\Users\praus\Desktop\Trabalhos\Eu\Programacao\flaskteste\venv\lib\site-packages\sqlalchemy\orm\session.py", line 1692, in execute
    result = conn._execute_20(statement, params or {}, execution_options)
  File "C:\Users\praus\Desktop\Trabalhos\Eu\Programacao\flaskteste\venv\lib\site-packages\sqlalchemy\engine\base.py", line 1631, in _execute_20
    return meth(self, args_10style, kwargs_10style, execution_options)
  File "C:\Users\praus\Desktop\Trabalhos\Eu\Programacao\flaskteste\venv\lib\site-packages\sqlalchemy\sql\elements.py", line 325, in _execute_on_connection
    return connection._execute_clauseelement(
  File "C:\Users\praus\Desktop\Trabalhos\Eu\Programacao\flaskteste\venv\lib\site-packages\sqlalchemy\engine\base.py", line 1498, in _execute_clauseelement
    ret = self._execute_context(
  File "C:\Users\praus\Desktop\Trabalhos\Eu\Programacao\flaskteste\venv\lib\site-packages\sqlalchemy\engine\base.py", line 1862, in _execute_context
    self._handle_dbapi_exception(
  File "C:\Users\praus\Desktop\Trabalhos\Eu\Programacao\flaskteste\venv\lib\site-packages\sqlalchemy\engine\base.py", line 2043, in _handle_dbapi_exception
    util.raise_(
  File "C:\Users\praus\Desktop\Trabalhos\Eu\Programacao\flaskteste\venv\lib\site-packages\sqlalchemy\util\compat.py", line 207, in raise_
    raise exception
  File "C:\Users\praus\Desktop\Trabalhos\Eu\Programacao\flaskteste\venv\lib\site-packages\sqlalchemy\engine\base.py", line 1819, in _execute_context
    self.dialect.do_execute(
  File "C:\Users\praus\Desktop\Trabalhos\Eu\Programacao\flaskteste\venv\lib\site-packages\sqlalchemy\engine\default.py", line 732, in do_execute
    cursor.execute(statement, parameters)
sqlalchemy.exc.OperationalError: (sqlite3.OperationalError) no such column: client_items.client_id
[SQL: SELECT client_items.id AS client_items_id, client_items.cpf AS client_items_cpf, client_items.name AS client_items_name, client_items.birthday AS client_items_birthday, client_items.client_id AS client_items_client_id 
FROM client_items]
(Background on this error at: https://sqlalche.me/e/14/e3q8)
ERROR:flask_migrate:Error: Directory migrations already exists and is not empty
ERROR:flask_migrate:Error: Directory migrations already exists and is not empty
INFO:root:Aplicativo iniciado
INFO:root:Servidor Gevent iniciado na porta 5000
ERROR:app:Exception on /dashboard [GET]
Traceback (most recent call last):
  File "C:\Users\praus\Desktop\Trabalhos\Eu\Programacao\flaskteste\venv\lib\site-packages\flask\app.py", line 2077, in wsgi_app
    response = self.full_dispatch_request()
  File "C:\Users\praus\Desktop\Trabalhos\Eu\Programacao\flaskteste\venv\lib\site-packages\flask\app.py", line 1525, in full_dispatch_request
    rv = self.handle_user_exception(e)
  File "C:\Users\praus\Desktop\Trabalhos\Eu\Programacao\flaskteste\venv\lib\site-packages\flask\app.py", line 1523, in full_dispatch_request
    rv = self.dispatch_request()
  File "C:\Users\praus\Desktop\Trabalhos\Eu\Programacao\flaskteste\venv\lib\site-packages\flask\app.py", line 1509, in dispatch_request
    return self.ensure_sync(self.view_functions[rule.endpoint])(**req.view_args)
  File "C:\Users\praus\Desktop\Trabalhos\Eu\Programacao\flaskteste\venv\lib\site-packages\flask_login\utils.py", line 277, in decorated_view
    return current_app.ensure_sync(func)(*args, **kwargs)
  File "C:\Users\praus\Desktop\Trabalhos\Eu\Programacao\flaskteste\app.py", line 173, in dashboard
    return render_template('dashboard.html', items=user_names, client_items=client_items)
  File "C:\Users\praus\Desktop\Trabalhos\Eu\Programacao\flaskteste\venv\lib\site-packages\flask\templating.py", line 148, in render_template
    return _render(
  File "C:\Users\praus\Desktop\Trabalhos\Eu\Programacao\flaskteste\venv\lib\site-packages\flask\templating.py", line 128, in _render
    rv = template.render(context)
  File "C:\Users\praus\Desktop\Trabalhos\Eu\Programacao\flaskteste\venv\lib\site-packages\jinja2\environment.py", line 1291, in render
    self.environment.handle_exception()
  File "C:\Users\praus\Desktop\Trabalhos\Eu\Programacao\flaskteste\venv\lib\site-packages\jinja2\environment.py", line 926, in handle_exception
    raise rewrite_traceback_stack(source=source)
  File "C:\Users\praus\Desktop\Trabalhos\Eu\Programacao\flaskteste\templates\dashboard.html", line 1, in top-level template code
    {% extends 'header.html' %}
  File "C:\Users\praus\Desktop\Trabalhos\Eu\Programacao\flaskteste\templates\header.html", line 26, in top-level template code
    {% block content %}
  File "C:\Users\praus\Desktop\Trabalhos\Eu\Programacao\flaskteste\templates\dashboard.html", line 20, in block 'content'
    <form action="{{url_for('new_client')}}" method="post">
  File "C:\Users\praus\Desktop\Trabalhos\Eu\Programacao\flaskteste\venv\lib\site-packages\flask\helpers.py", line 336, in url_for
    return appctx.app.handle_url_build_error(error, endpoint, values)
  File "C:\Users\praus\Desktop\Trabalhos\Eu\Programacao\flaskteste\venv\lib\site-packages\flask\helpers.py", line 323, in url_for
    rv = url_adapter.build(
  File "C:\Users\praus\Desktop\Trabalhos\Eu\Programacao\flaskteste\venv\lib\site-packages\werkzeug\routing.py", line 2307, in build
    raise BuildError(endpoint, values, method, self)
werkzeug.routing.BuildError: Could not build url for endpoint 'new_client'. Did you mean 'login' instead?
INFO:root:Aplicativo iniciado
INFO:root:Servidor Gevent iniciado na porta 5000
INFO:root:Aplicativo iniciado
WARNING:app:WebSocket transport not available. Install gevent-websocket for improved performance.
INFO:werkzeug: * Restarting with stat
INFO:root:Aplicativo iniciado
WARNING:werkzeug: * Debugger is active!
INFO:werkzeug: * Debugger PIN: 681-882-444
WARNING:app:WebSocket transport not available. Install gevent-websocket for improved performance.
INFO:root:Servidor Gevent iniciado na porta 5000
INFO:root:Servidor Gevent iniciado na porta 5000
INFO:root:Aplicativo iniciado
INFO:root:Servidor Gevent iniciado na porta 5000
WARNING:app:WebSocket transport not available. Install gevent-websocket for improved performance.
INFO:werkzeug: * Restarting with stat
INFO:root:Aplicativo iniciado
INFO:root:Servidor Gevent iniciado na porta 5000
WARNING:werkzeug: * Debugger is active!
INFO:werkzeug: * Debugger PIN: 681-882-444
WARNING:app:WebSocket transport not available. Install gevent-websocket for improved performance.
INFO:werkzeug: * Detected change in 'C:\\Users\\Admin\\Desktop\\Leonardo Worm\\Testes\\Flask teste\\app.py', reloading
INFO:werkzeug: * Restarting with stat
INFO:root:Aplicativo iniciado
INFO:root:Servidor Gevent iniciado na porta 5000
WARNING:werkzeug: * Debugger is active!
INFO:werkzeug: * Debugger PIN: 681-882-444
WARNING:app:WebSocket transport not available. Install gevent-websocket for improved performance.
INFO:root:Aplicativo iniciado
INFO:root:Servidor Gevent iniciado na porta 5000
WARNING:app:WebSocket transport not available. Install gevent-websocket for improved performance.
INFO:werkzeug: * Restarting with stat
INFO:root:Aplicativo iniciado
INFO:root:Servidor Gevent iniciado na porta 5000
WARNING:werkzeug: * Debugger is active!
INFO:werkzeug: * Debugger PIN: 681-882-444
WARNING:app:WebSocket transport not available. Install gevent-websocket for improved performance.
INFO:werkzeug: * Detected change in 'C:\\Users\\Admin\\Desktop\\Leonardo Worm\\Testes\\Flask teste\\app.py', reloading
INFO:werkzeug: * Restarting with stat
INFO:root:Aplicativo iniciado
INFO:root:Servidor Gevent iniciado na porta 5000
WARNING:werkzeug: * Debugger is active!
INFO:werkzeug: * Debugger PIN: 681-882-444
WARNING:app:WebSocket transport not available. Install gevent-websocket for improved performance.
INFO:werkzeug: * Detected change in 'C:\\Users\\Admin\\Desktop\\Leonardo Worm\\Testes\\Flask teste\\app.py', reloading
INFO:werkzeug: * Restarting with stat
INFO:root:Aplicativo iniciado
INFO:root:Servidor Gevent iniciado na porta 5000
WARNING:werkzeug: * Debugger is active!
INFO:werkzeug: * Debugger PIN: 681-882-444
WARNING:app:WebSocket transport not available. Install gevent-websocket for improved performance.
INFO:werkzeug: * Detected change in 'C:\\Users\\Admin\\Desktop\\Leonardo Worm\\Testes\\Flask teste\\app.py', reloading
INFO:werkzeug: * Restarting with stat
INFO:root:Aplicativo iniciado
INFO:root:Servidor Gevent iniciado na porta 5000
WARNING:werkzeug: * Debugger is active!
INFO:werkzeug: * Debugger PIN: 681-882-444
WARNING:app:WebSocket transport not available. Install gevent-websocket for improved performance.
INFO:werkzeug: * Detected change in 'C:\\Users\\Admin\\Desktop\\Leonardo Worm\\Testes\\Flask teste\\app.py', reloading
INFO:werkzeug: * Restarting with stat
INFO:root:Aplicativo iniciado
INFO:root:Servidor Gevent iniciado na porta 5000
WARNING:werkzeug: * Debugger is active!
INFO:werkzeug: * Debugger PIN: 681-882-444
WARNING:app:WebSocket transport not available. Install gevent-websocket for improved performance.
INFO:werkzeug: * Detected change in 'C:\\Users\\Admin\\Desktop\\Leonardo Worm\\Testes\\Flask teste\\app.py', reloading
INFO:werkzeug: * Restarting with stat
INFO:root:Aplicativo iniciado
INFO:root:Servidor Gevent iniciado na porta 5000
WARNING:app:WebSocket transport not available. Install gevent-websocket for improved performance.
INFO:werkzeug: * Restarting with stat
INFO:root:Aplicativo iniciado
INFO:root:Servidor Gevent iniciado na porta 5000
WARNING:werkzeug: * Debugger is active!
INFO:werkzeug: * Debugger PIN: 681-882-444
WARNING:app:WebSocket transport not available. Install gevent-websocket for improved performance.
INFO:werkzeug: * Detected change in 'C:\\Users\\Admin\\Desktop\\Leonardo Worm\\Testes\\Flask teste\\app.py', reloading
INFO:werkzeug: * Restarting with stat
INFO:root:Aplicativo iniciado
INFO:root:Servidor Gevent iniciado na porta 5000
WARNING:werkzeug: * Debugger is active!
INFO:werkzeug: * Debugger PIN: 681-882-444
WARNING:app:WebSocket transport not available. Install gevent-websocket for improved performance.
INFO:werkzeug: * Detected change in 'C:\\Users\\Admin\\Desktop\\Leonardo Worm\\Testes\\Flask teste\\app.py', reloading
INFO:werkzeug: * Restarting with stat
INFO:root:Aplicativo iniciado
INFO:root:Servidor Gevent iniciado na porta 5000
WARNING:werkzeug: * Debugger is active!
INFO:werkzeug: * Debugger PIN: 681-882-444
WARNING:app:WebSocket transport not available. Install gevent-websocket for improved performance.
INFO:werkzeug: * Detected change in 'C:\\Users\\Admin\\Desktop\\Leonardo Worm\\Testes\\Flask teste\\app.py', reloading
INFO:werkzeug: * Restarting with stat
INFO:root:Aplicativo iniciado
INFO:root:Servidor Gevent iniciado na porta 5000
WARNING:werkzeug: * Debugger is active!
INFO:werkzeug: * Debugger PIN: 681-882-444
WARNING:app:WebSocket transport not available. Install gevent-websocket for improved performance.
INFO:werkzeug: * Detected change in 'C:\\Users\\Admin\\Desktop\\Leonardo Worm\\Testes\\Flask teste\\app.py', reloading
INFO:werkzeug: * Restarting with stat
INFO:root:Aplicativo iniciado
INFO:root:Servidor Gevent iniciado na porta 5000
WARNING:werkzeug: * Debugger is active!
INFO:werkzeug: * Debugger PIN: 681-882-444
WARNING:app:WebSocket transport not available. Install gevent-websocket for improved performance.
INFO:werkzeug: * Detected change in 'C:\\Users\\Admin\\Desktop\\Leonardo Worm\\Testes\\Flask teste\\app.py', reloading
INFO:werkzeug: * Restarting with stat
INFO:root:Aplicativo iniciado
INFO:root:Servidor Gevent iniciado na porta 5000
WARNING:app:WebSocket transport not available. Install gevent-websocket for improved performance.
INFO:werkzeug: * Restarting with stat
INFO:root:Aplicativo iniciado
INFO:root:Servidor Gevent iniciado na porta 5000
WARNING:werkzeug: * Debugger is active!
INFO:werkzeug: * Debugger PIN: 681-882-444
WARNING:app:WebSocket transport not available. Install gevent-websocket for improved performance.
INFO:root:Aplicativo iniciado
INFO:root:Servidor Gevent iniciado na porta 5000
WARNING:app:WebSocket transport not available. Install gevent-websocket for improved performance.
INFO:werkzeug: * Restarting with stat
INFO:root:Aplicativo iniciado
INFO:root:Servidor Gevent iniciado na porta 5000
WARNING:werkzeug: * Debugger is active!
INFO:werkzeug: * Debugger PIN: 681-882-444
WARNING:app:WebSocket transport not available. Install gevent-websocket for improved performance.
ERROR:engineio.server:The client is using an unsupported version of the Socket.IO or Engine.IO protocols (further occurrences of this error will be logged with level INFO)
INFO:werkzeug: * Detected change in 'C:\\Users\\Admin\\Desktop\\Leonardo Worm\\Testes\\Flask teste\\app.py', reloading
INFO:werkzeug: * Restarting with stat
INFO:root:Aplicativo iniciado
INFO:root:Servidor Gevent iniciado na porta 5000
WARNING:werkzeug: * Debugger is active!
INFO:werkzeug: * Debugger PIN: 681-882-444
WARNING:app:WebSocket transport not available. Install gevent-websocket for improved performance.
ERROR:engineio.server:The client is using an unsupported version of the Socket.IO or Engine.IO protocols (further occurrences of this error will be logged with level INFO)
INFO:root:Aplicativo iniciado
INFO:root:Servidor Gevent iniciado na porta 5000
WARNING:app:WebSocket transport not available. Install gevent-websocket for improved performance.
INFO:werkzeug: * Restarting with stat
INFO:root:Aplicativo iniciado
INFO:root:Servidor Gevent iniciado na porta 5000
WARNING:werkzeug: * Debugger is active!
INFO:werkzeug: * Debugger PIN: 681-882-444
WARNING:app:WebSocket transport not available. Install gevent-websocket for improved performance.
ERROR:engineio.server:The client is using an unsupported version of the Socket.IO or Engine.IO protocols (further occurrences of this error will be logged with level INFO)
INFO:werkzeug: * Detected change in 'C:\\Users\\Admin\\Desktop\\Leonardo Worm\\Testes\\Flask teste\\app.py', reloading
INFO:werkzeug: * Restarting with stat
INFO:root:Aplicativo iniciado
INFO:root:Servidor Gevent iniciado na porta 5000
WARNING:werkzeug: * Debugger is active!
INFO:werkzeug: * Debugger PIN: 681-882-444
WARNING:app:WebSocket transport not available. Install gevent-websocket for improved performance.
INFO:werkzeug: * Detected change in 'C:\\Users\\Admin\\Desktop\\Leonardo Worm\\Testes\\Flask teste\\app.py', reloading
INFO:werkzeug: * Restarting with stat
INFO:root:Aplicativo iniciado
INFO:root:Servidor Gevent iniciado na porta 5000
WARNING:werkzeug: * Debugger is active!
INFO:werkzeug: * Debugger PIN: 681-882-444
WARNING:app:WebSocket transport not available. Install gevent-websocket for improved performance.
ERROR:engineio.server:The client is using an unsupported version of the Socket.IO or Engine.IO protocols (further occurrences of this error will be logged with level INFO)
INFO:root:Aplicativo iniciado
INFO:root:Servidor Gevent iniciado na porta 5000
WARNING:app:WebSocket transport not available. Install gevent-websocket for improved performance.
INFO:werkzeug: * Restarting with stat
INFO:root:Aplicativo iniciado
INFO:root:Servidor Gevent iniciado na porta 5000
WARNING:werkzeug: * Debugger is active!
INFO:werkzeug: * Debugger PIN: 681-882-444
WARNING:app:WebSocket transport not available. Install gevent-websocket for improved performance.
ERROR:engineio.server:The client is using an unsupported version of the Socket.IO or Engine.IO protocols (further occurrences of this error will be logged with level INFO)
INFO:werkzeug: * Detected change in 'C:\\Users\\Admin\\Desktop\\Leonardo Worm\\Testes\\Flask teste\\app.py', reloading
INFO:werkzeug: * Restarting with stat
INFO:root:Aplicativo iniciado
INFO:root:Servidor Gevent iniciado na porta 5000
WARNING:werkzeug: * Debugger is active!
INFO:werkzeug: * Debugger PIN: 681-882-444
WARNING:app:WebSocket transport not available. Install gevent-websocket for improved performance.
INFO:werkzeug: * Detected change in 'C:\\Users\\Admin\\Desktop\\Leonardo Worm\\Testes\\Flask teste\\app.py', reloading
INFO:werkzeug: * Restarting with stat
INFO:root:Aplicativo iniciado
INFO:root:Servidor Gevent iniciado na porta 5000
WARNING:werkzeug: * Debugger is active!
INFO:werkzeug: * Debugger PIN: 681-882-444
WARNING:app:WebSocket transport not available. Install gevent-websocket for improved performance.
INFO:root:Aplicativo iniciado
INFO:root:Servidor Gevent iniciado na porta 5000
WARNING:app:WebSocket transport not available. Install gevent-websocket for improved performance.
INFO:werkzeug: * Restarting with stat
INFO:root:Aplicativo iniciado
INFO:root:Servidor Gevent iniciado na porta 5000
WARNING:werkzeug: * Debugger is active!
INFO:werkzeug: * Debugger PIN: 681-882-444
WARNING:app:WebSocket transport not available. Install gevent-websocket for improved performance.
ERROR:engineio.server:The client is using an unsupported version of the Socket.IO or Engine.IO protocols (further occurrences of this error will be logged with level INFO)
INFO:werkzeug: * Detected change in 'C:\\Users\\Admin\\Desktop\\Leonardo Worm\\Testes\\Flask teste\\app.py', reloading
INFO:werkzeug: * Restarting with stat
